<?xml version="1.0" ?>
<!-- =================================================================================== -->
<!-- |    This document was autogenerated by xacro from /home/kh22/etaf_ws/install/etaf_gazebo/share/etaf_gazebo/models/etaf_vehicle/model.urdf.xacro | -->
<!-- |    EDITING THIS FILE BY HAND IS NOT RECOMMENDED                                 | -->
<!-- =================================================================================== -->
<sdf version="1.6">
  <!-- Sensor Macros -->
  <model name="etaf_vehicle">
    <static>false</static>
    <!-- ****************** ROBOT BASE FOOTPRINT ***************************  -->
    <pose>0.0 0.0 0.0 0.0 0.0 0.0</pose>
    <link name="base_footprint"/>
    <!-- Base Link -->
    <link name="base_link">
      <pose>0 0 0.15 0 0 0</pose>
      <inertial>
        <mass>700.0</mass>
        <inertia>
          <ixx>1.0</ixx>
          <ixy>0.0</ixy>
          <ixz>0.0</ixz>
          <iyy>1.0</iyy>
          <iyz>0.0</iyz>
          <izz>1.0</izz>
        </inertia>
      </inertial>
      <collision name="base_collision">
        <geometry>
          <box>
            <size>1.8 0.96 0.3</size>
          </box>
        </geometry>
      </collision>
      <visual name="base_visual">
        <origin rpy="0 0 0" xyz="0 0 0.15"/>
        <geometry>
          <mesh>
            <uri>model://etaf_vehicle/meshes/robot_base.stl</uri>
            <scale>0.001 0.001 0.001</scale>
          </mesh>
        </geometry>
        <material>
          <ambient>1.0 0.0 0.0 1.0</ambient>
          <diffuse>1.0 0.0 0.0 1.0</diffuse>
          <specular>0.2 0.2 0.2 1.0</specular>
          <emissive>0.0 0.0 0.0 1.0</emissive>
        </material>
      </visual>
      <!-- Sensors -
      <xacro:camera_sensor name="front_camera" parent_link="base_link"/>
      <xacro:lidar_sensor name="lds_lidar" parent_link="base_link"/>
      <xacro:imu_sensor name="inertial_unit" parent_link="base_link"/>-->
    </link>
    <!-- ************************ JOINTS ***********************************  -->
    <!-- Pose of the joint is the same as the child link frame -->
    <!-- Axis is the axis of rotation relative to the child link frame -->
    <joint name="base_joint" type="fixed">
      <parent>base_footprint</parent>
      <child>base_link</child>
      <pose>0 0 0 0 0 0</pose>
    </joint>
    <link name="front_camera_link">
      <pose>0.9 0 0.3 0 0 0</pose>
      <visual name="front_camera_visual">
        <geometry>
          <box>
            <size>0.05 0.05 0.05</size>
          </box>
        </geometry>
        <material>
          <ambient>1.0 1.0 0.0 1.0</ambient>
          <diffuse>1.0 1.0 0.0 1.0</diffuse>
          <specular>0.2 0.2 0.2 1.0</specular>
          <emissive>0.0 0.0 0.0 1.0</emissive>
        </material>
      </visual>
      <inertial>
        <mass>0.1</mass>
        <inertia>
          <ixx>1e-5</ixx>
          <iyy>1e-5</iyy>
          <izz>1e-5</izz>
          <ixy>0</ixy>
          <ixz>0</ixz>
          <iyz>0</iyz>
        </inertia>
      </inertial>
      <sensor name="front_camera" type="camera">
        <always_on>true</always_on>
        <update_rate>30</update_rate>
        <visualize>true</visualize>
        <topic>camera/image_raw</topic>
        <gz_frame_id>camera_rgb_frame</gz_frame_id>
        <camera>
          <camera_info_topic>camera/camera_info</camera_info_topic>
          <horizontal_fov>1.047</horizontal_fov>
          <image>
            <width>640</width>
            <height>480</height>
            <format>R8G8B8</format>
          </image>
          <clip>
            <near>0.1</near>
            <far>100</far>
          </clip>
        </camera>
        <plugin filename="gz-sim-sensors-system" name="gz::sim::systems::Sensors">
          <topic>/image</topic>
        </plugin>
      </sensor>
    </link>
    <joint name="front_camera_joint" type="fixed">
      <parent>base_link</parent>
      <child>front_camera_link</child>
      <pose>0 0 0 0 0 0</pose>
      <axis>
        <xyz>0 0 1</xyz>
      </axis>
    </joint>
    <link name="inertial_unit_link">
      <gravity>true</gravity>
      <sensor name="inertial_unit" type="imu">
        <pose>0 0 0.2 0 0 0</pose>
        <always_on>1</always_on>
        <update_rate>100.0</update_rate>
        <plugin filename="libignition-gazebo-imu-system.so" name="ignition::gazebo::systems::Imu">
          <topic>imu</topic>
        </plugin>
      </sensor>
    </link>
    <link name="drivewhl_left_f_link">
      <pose>0 0 0 0 0 0</pose>
      <inertial>
        <mass>10.0</mass>
        <inertia>
          <ixx>0.01</ixx>
          <ixy>0</ixy>
          <ixz>0</ixz>
          <iyy>0.01</iyy>
          <iyz>0</iyz>
          <izz>0.01</izz>
        </inertia>
      </inertial>
      <collision name="drivewhl_left_f_collision">
        <pose>0.8 0.65 0.15 1.5708 0 0</pose>
        <!-- Rotate cylinder to face +Y -->
        <geometry>
          <cylinder>
            <radius>0.15</radius>
            <length>0.25</length>
          </cylinder>
        </geometry>
      </collision>
      <visual name="drivewhl_left_f_visual">
        <pose>0.8 0.65 0.15 1.5708 0 0</pose>
        <!-- Rotate cylinder to face +Y -->
        <geometry>
          <cylinder>
            <radius>0.15</radius>
            <length>0.25</length>
          </cylinder>
        </geometry>
      </visual>
    </link>
    <joint name="drivewhl_left_f_joint" type="revolute">
      <pose>0.8 0.65 0.15 0 0 0</pose>
      <parent>base_link</parent>
      <child>drivewhl_left_f_link</child>
      <axis>
        <xyz>0 1 0</xyz>
      </axis>
    </joint>
    <link name="drivewhl_right_f_link">
      <pose>0 0 0 0 0 0</pose>
      <inertial>
        <mass>10.0</mass>
        <inertia>
          <ixx>0.01</ixx>
          <ixy>0</ixy>
          <ixz>0</ixz>
          <iyy>0.01</iyy>
          <iyz>0</iyz>
          <izz>0.01</izz>
        </inertia>
      </inertial>
      <collision name="drivewhl_right_f_collision">
        <pose>0.8 -0.65 0.15 1.5708 0 0</pose>
        <!-- Rotate cylinder to face +Y -->
        <geometry>
          <cylinder>
            <radius>0.15</radius>
            <length>0.25</length>
          </cylinder>
        </geometry>
      </collision>
      <visual name="drivewhl_right_f_visual">
        <pose>0.8 -0.65 0.15 1.5708 0 0</pose>
        <!-- Rotate cylinder to face +Y -->
        <geometry>
          <cylinder>
            <radius>0.15</radius>
            <length>0.25</length>
          </cylinder>
        </geometry>
      </visual>
    </link>
    <joint name="drivewhl_right_f_joint" type="revolute">
      <pose>0.8 -0.65 0.15 0 0 0</pose>
      <parent>base_link</parent>
      <child>drivewhl_right_f_link</child>
      <axis>
        <xyz>0 1 0</xyz>
      </axis>
    </joint>
    <link name="drivewhl_left_r_link">
      <pose>0 0 0 0 0 0</pose>
      <inertial>
        <mass>10.0</mass>
        <inertia>
          <ixx>0.01</ixx>
          <ixy>0</ixy>
          <ixz>0</ixz>
          <iyy>0.01</iyy>
          <iyz>0</iyz>
          <izz>0.01</izz>
        </inertia>
      </inertial>
      <collision name="drivewhl_left_r_collision">
        <pose>-0.8 0.65 0.15 1.5708 0 0</pose>
        <!-- Rotate cylinder to face +Y -->
        <geometry>
          <cylinder>
            <radius>0.15</radius>
            <length>0.25</length>
          </cylinder>
        </geometry>
      </collision>
      <visual name="drivewhl_left_r_visual">
        <pose>-0.8 0.65 0.15 1.5708 0 0</pose>
        <!-- Rotate cylinder to face +Y -->
        <geometry>
          <cylinder>
            <radius>0.15</radius>
            <length>0.25</length>
          </cylinder>
        </geometry>
      </visual>
    </link>
    <joint name="drivewhl_left_r_joint" type="revolute">
      <pose>-0.8 0.65 0.15 0 0 0</pose>
      <parent>base_link</parent>
      <child>drivewhl_left_r_link</child>
      <axis>
        <xyz>0 1 0</xyz>
      </axis>
    </joint>
    <link name="drivewhl_right_r_link">
      <pose>0 0 0 0 0 0</pose>
      <inertial>
        <mass>10.0</mass>
        <inertia>
          <ixx>0.01</ixx>
          <ixy>0</ixy>
          <ixz>0</ixz>
          <iyy>0.01</iyy>
          <iyz>0</iyz>
          <izz>0.01</izz>
        </inertia>
      </inertial>
      <collision name="drivewhl_right_r_collision">
        <pose>-0.8 -0.65 0.15 1.5708 0 0</pose>
        <!-- Rotate cylinder to face +Y -->
        <geometry>
          <cylinder>
            <radius>0.15</radius>
            <length>0.25</length>
          </cylinder>
        </geometry>
      </collision>
      <visual name="drivewhl_right_r_visual">
        <pose>-0.8 -0.65 0.15 1.5708 0 0</pose>
        <!-- Rotate cylinder to face +Y -->
        <geometry>
          <cylinder>
            <radius>0.15</radius>
            <length>0.25</length>
          </cylinder>
        </geometry>
      </visual>
    </link>
    <joint name="drivewhl_right_r_joint" type="revolute">
      <pose>-0.8 -0.65 0.15 0 0 0</pose>
      <parent>base_link</parent>
      <child>drivewhl_right_r_link</child>
      <axis>
        <xyz>0 1 0</xyz>
      </axis>
    </joint>
    <!-- Plugin to use ROS2 DiffDrive -->
    <plugin filename="gz-sim-diff-drive-system" name="gz::sim::systems::DiffDrive">
      <!-- wheels -->
      <left_joint>drivewhl_left_f_joint</left_joint>
      <left_joint>drivewhl_left_r_joint</left_joint>
      <right_joint>drivewhl_right_f_joint</right_joint>
      <right_joint>drivewhl_right_r_joint</right_joint>
      <!-- kinematics -->
      <wheel_separation>1.3</wheel_separation>
      <wheel_radius>0.15</wheel_radius>
      <!-- limits -->
      <max_linear_acceleration>1.0</max_linear_acceleration>
      <topic>cmd_vel</topic>
      <odom_topic>odom</odom_topic>
      <frame_id>odom</frame_id>
      <tf_topic>/tf</tf_topic>
      <odom_publisher_frequency>30</odom_publisher_frequency>
      <child_frame_id>base_footprint</child_frame_id>
      <ros>
        <namespace>/</namespace>
        <!-- put ROS topics at root -->
        <remapping>cmd_vel:=cmd_vel</remapping>
        <remapping>odom:=odom</remapping>
      </ros>
    </plugin>
    <!-- Plugin to publish joint states and broadcast TF -->
    <plugin filename="gz-sim-joint-state-publisher-system" name="gz::sim::systems::JointStatePublisher">
      <topic>joint_states</topic>
      <publish_frequency>50</publish_frequency>
      <update_rate>30</update_rate>
      <!--<joint_name_suffix>_joint</joint_name_suffix>-->
      <joint_name>drivewhl_left_f_joint</joint_name>
      <joint_name>drivewhl_right_f_joint</joint_name>
      <joint_name>drivewhl_left_r_joint</joint_name>
      <joint_name>drivewhl_right_r_joint</joint_name>
    </plugin>
  </model>
</sdf>
